{"uuid": "6378ea14-0037-4106-a993-f249b80f3232", "children": ["a1d2d272-8f06-4dae-b0f3-2855da22be06", "566841e2-46c4-4490-96b8-1475b7480424", "762f2176-7ed9-4de5-b7c8-1913391f9410"], "befores": [{"name": "driver", "status": "broken", "statusDetails": {"message": "selenium.common.exceptions.WebDriverException: Message: Error executing adbExec. Original error: 'Command ''C:\\Users\\PC\\AppData\\Local\\Android\\Sdk\\platform-tools\\adb.exe' -P 5037 -s emulator-5554 shell 'settings delete global hidden_api_policy_pre_p_apps;settings delete global hidden_api_policy_p_apps;settings delete global hidden_api_policy'' exited with code 1'; Command output: adb.exe: device still authorizing\r\n\nStacktrace:\nUnknownError: Error executing adbExec. Original error: 'Command ''C:\\Users\\PC\\AppData\\Local\\Android\\Sdk\\platform-tools\\adb.exe' -P 5037 -s emulator-5554 shell 'settings delete global hidden_api_policy_pre_p_apps;settings delete global hidden_api_policy_p_apps;settings delete global hidden_api_policy'' exited with code 1'; Command output: adb.exe: device still authorizing\r\n\n    at getResponseForW3CError (C:\\Users\\PC\\AppData\\Roaming\\npm\\node_modules\\appium\\node_modules\\@appium\\base-driver\\lib\\protocol\\errors.ts:1103:34)\n    at asyncHandler (C:\\Users\\PC\\AppData\\Roaming\\npm\\node_modules\\appium\\node_modules\\@appium\\base-driver\\lib\\protocol\\protocol.ts:507:57)\nThe above error is caused by\nError: Error executing adbExec. Original error: 'Command ''C:\\Users\\PC\\AppData\\Local\\Android\\Sdk\\platform-tools\\adb.exe' -P 5037 -s emulator-5554 shell 'settings delete global hidden_api_policy_pre_p_apps;settings delete global hidden_api_policy_p_apps;settings delete global hidden_api_policy'' exited with code 1'; Command output: adb.exe: device still authorizing\r\n\n    at ChildProcess.<anonymous> (C:\\Users\\PC\\.appium\\node_modules\\appium-uiautomator2-driver\\node_modules\\teen_process\\lib\\exec.js:110:19)\n    at ChildProcess.emit (node:events:519:28)\n    at maybeClose (node:internal/child_process:1101:16)\n    at Process.ChildProcess._handle.onexit (node:internal/child_process:304:5)\n    at Process.callbackTrampoline (node:internal/async_hooks:130:17)\n", "trace": "  File \"C:\\Users\\PC\\AppData\\Local\\Programs\\Python\\Python313\\Lib\\site-packages\\pluggy\\_callers.py\", line 38, in run_old_style_hookwrapper\n    res = yield\n          ^^^^^\n  File \"C:\\Users\\PC\\AppData\\Local\\Programs\\Python\\Python313\\Lib\\site-packages\\pluggy\\_callers.py\", line 139, in _multicall\n    teardown.throw(exception)\n    ~~~~~~~~~~~~~~^^^^^^^^^^^\n  File \"C:\\Users\\PC\\AppData\\Local\\Programs\\Python\\Python313\\Lib\\site-packages\\_pytest\\setuponly.py\", line 36, in pytest_fixture_setup\n    return (yield)\n            ^^^^^\n  File \"C:\\Users\\PC\\AppData\\Local\\Programs\\Python\\Python313\\Lib\\site-packages\\pluggy\\_callers.py\", line 121, in _multicall\n    res = hook_impl.function(*args)\n  File \"C:\\Users\\PC\\AppData\\Local\\Programs\\Python\\Python313\\Lib\\site-packages\\_pytest\\fixtures.py\", line 1196, in pytest_fixture_setup\n    result = call_fixture_func(fixturefunc, request, kwargs)\n  File \"C:\\Users\\PC\\AppData\\Local\\Programs\\Python\\Python313\\Lib\\site-packages\\_pytest\\fixtures.py\", line 923, in call_fixture_func\n    fixture_result = next(generator)\n  File \"C:\\Users\\PC\\Documents\\Latihan_Automasi\\conftest.py\", line 22, in driver\n    appium_driver = webdriver.Remote(\"http://localhost:4723\", options=appium_options)\n  File \"C:\\Users\\PC\\AppData\\Local\\Programs\\Python\\Python313\\Lib\\site-packages\\appium\\webdriver\\webdriver.py\", line 249, in __init__\n    super().__init__(\n    ~~~~~~~~~~~~~~~~^\n        command_executor=command_executor,\n        ^^^^^^^^^^^^^^^^^^^^^^^^^^^^^^^^^^\n    ...<3 lines>...\n        client_config=client_config,\n        ^^^^^^^^^^^^^^^^^^^^^^^^^^^^\n    )\n    ^\n  File \"C:\\Users\\PC\\AppData\\Local\\Programs\\Python\\Python313\\Lib\\site-packages\\selenium\\webdriver\\remote\\webdriver.py\", line 263, in __init__\n    self.start_session(capabilities)\n    ~~~~~~~~~~~~~~~~~~^^^^^^^^^^^^^^\n  File \"C:\\Users\\PC\\AppData\\Local\\Programs\\Python\\Python313\\Lib\\site-packages\\appium\\webdriver\\webdriver.py\", line 342, in start_session\n    response = self.execute(RemoteCommand.NEW_SESSION, w3c_caps)\n  File \"C:\\Users\\PC\\AppData\\Local\\Programs\\Python\\Python313\\Lib\\site-packages\\selenium\\webdriver\\remote\\webdriver.py\", line 458, in execute\n    self.error_handler.check_response(response)\n    ~~~~~~~~~~~~~~~~~~~~~~~~~~~~~~~~~^^^^^^^^^^\n  File \"C:\\Users\\PC\\AppData\\Local\\Programs\\Python\\Python313\\Lib\\site-packages\\selenium\\webdriver\\remote\\errorhandler.py\", line 232, in check_response\n    raise exception_class(message, screen, stacktrace)\n"}, "start": 1760363309218, "stop": 1760363317832}], "start": 1760363309218, "stop": 1760363318140}