{"uuid": "1023f86c-a0d8-47dd-b188-5972b72c38ed", "children": ["5a7b651e-4dba-42d9-9dba-b00c872a8f5b", "45551e80-106d-495e-b80e-409aa01f0fb4", "e1c47b7e-2f70-459a-bd5f-c70fb6036723"], "befores": [{"name": "driver", "status": "broken", "statusDetails": {"message": "selenium.common.exceptions.WebDriverException: Message: Either provide 'app' option to install 'com.google.android.calculator' or consider setting 'noReset' to 'true' if 'com.google.android.calculator' is supposed to be preinstalled.\nStacktrace:\nUnknownError: Either provide 'app' option to install 'com.google.android.calculator' or consider setting 'noReset' to 'true' if 'com.google.android.calculator' is supposed to be preinstalled.\n    at getResponseForW3CError (C:\\Users\\PC\\AppData\\Roaming\\npm\\node_modules\\appium\\node_modules\\@appium\\base-driver\\lib\\protocol\\errors.ts:1103:34)\n    at asyncHandler (C:\\Users\\PC\\AppData\\Roaming\\npm\\node_modules\\appium\\node_modules\\@appium\\base-driver\\lib\\protocol\\protocol.ts:507:57)\nThe above error is caused by\nError: Either provide 'app' option to install 'com.google.android.calculator' or consider setting 'noReset' to 'true' if 'com.google.android.calculator' is supposed to be preinstalled.\n    at AndroidUiautomator2Driver.resetAUT (C:\\Users\\PC\\.appium\\node_modules\\appium-uiautomator2-driver\\node_modules\\appium-android-driver\\lib\\commands\\app-management.js:410:11)\n    at AndroidUiautomator2Driver.initAUT (C:\\Users\\PC\\.appium\\node_modules\\appium-uiautomator2-driver\\lib\\driver.ts:794:9)\n", "trace": "  File \"C:\\Users\\PC\\AppData\\Local\\Programs\\Python\\Python313\\Lib\\site-packages\\pluggy\\_callers.py\", line 38, in run_old_style_hookwrapper\n    res = yield\n          ^^^^^\n  File \"C:\\Users\\PC\\AppData\\Local\\Programs\\Python\\Python313\\Lib\\site-packages\\pluggy\\_callers.py\", line 139, in _multicall\n    teardown.throw(exception)\n    ~~~~~~~~~~~~~~^^^^^^^^^^^\n  File \"C:\\Users\\PC\\AppData\\Local\\Programs\\Python\\Python313\\Lib\\site-packages\\_pytest\\setuponly.py\", line 36, in pytest_fixture_setup\n    return (yield)\n            ^^^^^\n  File \"C:\\Users\\PC\\AppData\\Local\\Programs\\Python\\Python313\\Lib\\site-packages\\pluggy\\_callers.py\", line 121, in _multicall\n    res = hook_impl.function(*args)\n  File \"C:\\Users\\PC\\AppData\\Local\\Programs\\Python\\Python313\\Lib\\site-packages\\_pytest\\fixtures.py\", line 1196, in pytest_fixture_setup\n    result = call_fixture_func(fixturefunc, request, kwargs)\n  File \"C:\\Users\\PC\\AppData\\Local\\Programs\\Python\\Python313\\Lib\\site-packages\\_pytest\\fixtures.py\", line 923, in call_fixture_func\n    fixture_result = next(generator)\n  File \"C:\\Users\\PC\\Documents\\Latihan_Automasi\\conftest.py\", line 19, in driver\n    appium_driver = webdriver.Remote(\"http://localhost:4723\", options=appium_options)\n  File \"C:\\Users\\PC\\AppData\\Local\\Programs\\Python\\Python313\\Lib\\site-packages\\appium\\webdriver\\webdriver.py\", line 249, in __init__\n    super().__init__(\n    ~~~~~~~~~~~~~~~~^\n        command_executor=command_executor,\n        ^^^^^^^^^^^^^^^^^^^^^^^^^^^^^^^^^^\n    ...<3 lines>...\n        client_config=client_config,\n        ^^^^^^^^^^^^^^^^^^^^^^^^^^^^\n    )\n    ^\n  File \"C:\\Users\\PC\\AppData\\Local\\Programs\\Python\\Python313\\Lib\\site-packages\\selenium\\webdriver\\remote\\webdriver.py\", line 263, in __init__\n    self.start_session(capabilities)\n    ~~~~~~~~~~~~~~~~~~^^^^^^^^^^^^^^\n  File \"C:\\Users\\PC\\AppData\\Local\\Programs\\Python\\Python313\\Lib\\site-packages\\appium\\webdriver\\webdriver.py\", line 342, in start_session\n    response = self.execute(RemoteCommand.NEW_SESSION, w3c_caps)\n  File \"C:\\Users\\PC\\AppData\\Local\\Programs\\Python\\Python313\\Lib\\site-packages\\selenium\\webdriver\\remote\\webdriver.py\", line 458, in execute\n    self.error_handler.check_response(response)\n    ~~~~~~~~~~~~~~~~~~~~~~~~~~~~~~~~~^^^^^^^^^^\n  File \"C:\\Users\\PC\\AppData\\Local\\Programs\\Python\\Python313\\Lib\\site-packages\\selenium\\webdriver\\remote\\errorhandler.py\", line 232, in check_response\n    raise exception_class(message, screen, stacktrace)\n"}, "start": 1760364223292, "stop": 1760364228952}], "start": 1760364223292, "stop": 1760364229207}